<robot name="red_robot">
  <mujoco>
    <compiler meshdir="../meshes" balanceinertia="true"/>
  </mujoco>
  <link name="Pelvis_Link">
    <inertial>
      <origin xyz="0.005 0.0 0.24" rpy="0 0 0" />
      <mass value="52.5" />
      <inertia ixx="0.794" ixy="0.0" ixz="0.0" iyy="0.5657" iyz="0.0" izz="0.5955" />
    </inertial>
    <visual>
      <origin xyz="0 0 0" rpy="0 0 0" />
      <geometry>
        <mesh filename="package://dyros_red_lowerbody_description/meshes/Pelvis_Link.stl" />
      </geometry>
      <material name="">
        <color rgba="0.20313 0.20313 0.20313 1" />
      </material>
    </visual>
    <collision>
      <origin xyz="0 0 0" rpy="0 0 0" />
      <geometry>
        <mesh filename="package://dyros_red_lowerbody_description/meshes/Pelvis_Link.stl" />
      </geometry>
    </collision>
  </link>
  <link name="HipRoll_L_Link">
    <inertial>
      <origin xyz="-0.06477 0 0.05149" rpy="0 0 0" />
      <mass value="2.874" />
      <inertia ixx="0.01954" ixy="-1.676E-07" ixz="-0.0008309" iyy="0.03348" iyz="-4.53E-09" izz="0.8081" />
    </inertial>
    <visual>
      <origin xyz="0 0 0" rpy="0 0 0" />
      <geometry>
        <mesh filename="package://dyros_red_lowerbody_description/meshes/HipRoll_L_Link.stl" />
      </geometry>
      <material name="">
        <color rgba="0.20313 0.20313 0.20313 1" />
      </material>
    </visual>
    <collision>
      <origin xyz="0 0 0" rpy="0 0 0" />
      <geometry>
        <mesh filename="package://dyros_red_lowerbody_description/meshes/HipRoll_L_Link.stl" />
      </geometry>
    </collision>
  </link>
  <joint name="HipRoll_L_Joint" type="revolute">
    <origin xyz="0 0.1025 -0.1225" rpy="0 0 0" />
    <parent link="Pelvis_Link" />
    <child link="HipRoll_L_Link" />
    <axis xyz="0 0 1" />
    <limit effort="50" lower="-0.2618" upper="0.2618" velocity="1.045"/>
    <dynamics damping="10" />
  </joint>
  <link name="HipCenter_L_Link">
    <inertial>
      <origin xyz="-0.04801 0.0022 2E-05" rpy="0 0 0" />
      <mass value="2.865" />
      <inertia ixx="1.075" ixy="1.725E-08" ixz="-3.236E-06" iyy="0.0983" iyz="-4.778E-06" izz="0.0094" />
    </inertial>
    <visual>
      <origin xyz="0 0 0" rpy="0 0 0" />
      <geometry>
        <mesh filename="package://dyros_red_lowerbody_description/meshes/HipCenter_L_Link.stl" />
      </geometry>
      <material name="">
        <color rgba="0.20313 0.20313 0.20313 1" />
      </material>
    </visual>
    <collision>
      <origin xyz="0 0 0" rpy="0 0 0" />
      <geometry>
        <mesh filename="package://dyros_red_lowerbody_description/meshes/HipCenter_L_Link.stl" />
      </geometry>
    </collision>

  </link>
  <joint name="HipCenter_L_Joint" type="revolute">
    <origin xyz="0 0 0" rpy="0 0 0" />
    <parent link="HipRoll_L_Link" />
    <child link="HipCenter_L_Link" />
    <axis xyz="1 0 0" />
    <limit effort="100" lower="-0.2618" upper="0.5236" velocity="2.09"/>
    <dynamics damping="10" />
  </joint>
  <link name="Thigh_L_Link">
    <inertial>
      <origin xyz="-0.00042 0.00032 -0.18904" rpy="0 0 0" />
      <mass value="5.756" />
      <inertia ixx="0.3204" ixy="-4.284E-05" ixz="-0.0002102" iyy="1.637" iyz="0.002581" izz="0.01053" />
    </inertial>
    <visual>
      <origin xyz="0 0 0" rpy="0 0 0" />
      <geometry>
        <mesh filename="package://dyros_red_lowerbody_description/meshes/Thigh_L_Link.stl" />
      </geometry>
      <material name="">
        <color rgba="0.85938 0.07813 0.23438 1" />
      </material>
    </visual>
    <collision>
      <origin xyz="0 0 0" rpy="0 0 0" />
      <geometry>
        <mesh filename="package://dyros_red_lowerbody_description/meshes/Thigh_L_Link.stl" />
      </geometry>
    </collision>
  </link>
  <joint name="Thigh_L_Joint" type="revolute">
    <origin xyz="0 0 0" rpy="0 0 0" />
    <parent link="HipCenter_L_Link" />
    <child link="Thigh_L_Link" />
    <axis xyz="0 1 0" />
    <limit effort="200" lower="-1.6581" upper="0.4014" velocity="2.09"/>
    <dynamics damping="10" />
  </joint>
  <link name="Knee_L_Link">
    <inertial>
      <origin xyz="0.00429 -0.00214 -0.1428" rpy="0 0 0" />
      <mass value="4.072" />
      <inertia ixx="0.1579" ixy="-2.887E-05" ixz="-0.002734" iyy="1.443" iyz="-0.001558" izz="0.007814" />
    </inertial>
    <visual>
      <origin xyz="0 0 0" rpy="0 0 0" />
      <geometry>
        <mesh filename="package://dyros_red_lowerbody_description/meshes/Knee_L_Link.stl" />
      </geometry>
      <material name="">
        <color rgba="0.85938 0.07813 0.23438 1" />
      </material>
    </visual>
    <collision>
      <origin xyz="0 0 0" rpy="0 0 0" />
      <geometry>
        <mesh filename="package://dyros_red_lowerbody_description/meshes/Knee_L_Link.stl" />
      </geometry>
    </collision>
  </link>
  <joint name="Knee_L_Joint" type="revolute">
    <origin xyz="0 0 -0.35" rpy="0 0 0" />
    <parent link="Thigh_L_Link" />
    <child link="Knee_L_Link" />
    <axis xyz="0 1 0" />
    <limit effort="200" lower="-0.0218" upper="1.9722" velocity="6.0"/>
    <dynamics damping="10" />
  </joint>
  <link name="AnkleCenter_L_Link">
    <inertial>
      <origin xyz="-0.00419 0.0018 -0.0003" rpy="0 0 0" />
      <mass value="2.693" />
      <inertia ixx="0.003065" ixy="-1.422E-07" ixz="2.222E-06" iyy="1.321" iyz="4.611E-06" izz="0.003589" />
    </inertial>
    <visual>
      <origin xyz="0 0 0" rpy="0 0 0" />
      <geometry>
        <mesh filename="package://dyros_red_lowerbody_description/meshes/AnkleCenter_L_Link.stl" />
      </geometry>
      <material name="">
        <color rgba="0.20313 0.20313 0.20313 1" />
      </material>
    </visual>
    <collision>
      <origin xyz="0 0 0" rpy="0 0 0" />
      <geometry>
        <mesh filename="package://dyros_red_lowerbody_description/meshes/AnkleCenter_L_Link.stl" />
      </geometry>
    </collision>
  </link>
  <joint name="AnkleCenter_L_Joint" type="revolute">
    <origin xyz="0 0 -0.35" rpy="0 0 0" />
    <parent link="Knee_L_Link" />
    <child link="AnkleCenter_L_Link" />
    <axis xyz="0 1 0" />
    <limit effort="200" lower="-1.5149" upper="1.7505" velocity="2.1"/>
    <dynamics damping="10" />
  </joint>
  <link name="AnkleRoll_L_Link">
    <inertial>
      <origin xyz="-0.00802 0 -0.08535" rpy="0 0 0" />
      <mass value="3.632" />
      <inertia ixx="0.4368" ixy="1.434E-05" ixz="-0.00496" iyy="0.0609" iyz="-2.508E-05" izz="0.02495" />
    </inertial>
    <visual>
      <origin xyz="0 0 0" rpy="0 0 0" />
      <geometry>
        <mesh filename="package://dyros_red_lowerbody_description/meshes/AnkleRoll_L_Link.stl" />
      </geometry>
      <material name="">
        <color rgba="0.85938 0.07813 0.23438 1" />
      </material>
    </visual>
    <collision>
      <origin xyz="0 0 0" rpy="0 0 0" />
      <geometry>
        <mesh filename="package://dyros_red_lowerbody_description/meshes/AnkleRoll_L_Link.stl"/>
      </geometry>
    </collision>
  </link>
  <joint name="AnkleRoll_L_Joint" type="revolute">
    <origin xyz="0 0 0" rpy="0 0 0" />
    <parent link="AnkleCenter_L_Link" />
    <child link="AnkleRoll_L_Link" />
    <axis xyz="1 0 0" />
    <limit effort="200" lower="-0.3491" upper="0.3491" velocity="2.1"/>
    <dynamics damping="10" />
  </joint>
  <joint name="LLeg_effector_fixedjoint" type="fixed">
    <parent link="AnkleRoll_L_Link"/>
    <child link="l_sole"/>
    <origin rpy="0 0 0" xyz="0 0 -0.1451"/>
    <axis xyz="0 0 0"/>
  </joint>
  <link name="l_sole"/>
  <link name="HipRoll_R_Link">
    <inertial>
      <origin xyz="-0.06477 0 0.05149" rpy="0 0 0" />
      <mass value="2.874" />
      <inertia ixx="0.01954" ixy="-1.676E-07" ixz="-0.0008309" iyy="0.03348" iyz="-4.53E-09" izz="0.8082" />
    </inertial>
    <visual>
      <origin xyz="0 0 0" rpy="0 0 0" />
      <geometry>
        <mesh filename="package://dyros_red_lowerbody_description/meshes/HipRoll_R_Link.stl" />
      </geometry>
      <material name="">
        <color rgba="0.20313 0.20313 0.20313 1" />
      </material>
    </visual>
    <collision>
      <origin xyz="0 0 0" rpy="0 0 0" />
      <geometry>
        <mesh filename="package://dyros_red_lowerbody_description/meshes/HipRoll_R_Link.stl" />
      </geometry>
    </collision>
  </link>
  <joint name="HipRoll_R_Joint" type="revolute">
    <origin xyz="0 -0.1025 -0.1225" rpy="0 0 0" />
    <parent link="Pelvis_Link" />
    <child link="HipRoll_R_Link" />
    <axis xyz="0 0 1" />
    <limit effort="50.0" lower="-0.2618" upper="0.2618" velocity="1.045"/>
    <dynamics damping="10" />
  </joint>
  <link name="HipCenter_R_Link">
    <inertial>
      <origin xyz="-0.04801 -0.0022 2E-05" rpy="0 0 0" />
      <mass value="2.865" />
      <inertia ixx="1.075" ixy="1.725E-08" ixz="-3.236E-06" iyy="0.009829" iyz="-4.778E-06" izz="0.009399" />
    </inertial>
    <visual>
      <origin xyz="0 0 0" rpy="0 0 0" />
      <geometry>
        <mesh filename="package://dyros_red_lowerbody_description/meshes/HipCenter_R_Link.stl" />
      </geometry>
      <material name="">
        <color rgba="0.20313 0.20313 0.20313 1" />
      </material>
    </visual>
    <collision>
      <origin xyz="0 0 0" rpy="0 0 0" />
      <geometry>
        <mesh filename="package://dyros_red_lowerbody_description/meshes/HipCenter_R_Link.stl" />
      </geometry>
    </collision>
  </link>
  <joint name="HipCenter_R_Joint" type="revolute">
    <origin xyz="0 0 0" rpy="0 0 0" />
    <parent link="HipRoll_R_Link" />
    <child link="HipCenter_R_Link" />
    <axis xyz="1 0 0" />
    <limit effort="200" lower="-0.5236" upper="0.2618" velocity="2.09"/>
    <dynamics damping="10" />
  </joint>
  <link name="Thigh_R_Link">
    <inertial>
      <origin xyz="-0.00042 -0.00032 -0.18904" rpy="0 0 0" />
      <mass value="5.756" />
      <inertia ixx="0.3204" ixy="-4.284E-05" ixz="-0.0002102" iyy="1.637" iyz="0.002581" izz="0.01053" />
    </inertial>
    <visual>
      <origin xyz="0 0 0" rpy="0 0 0" />
      <geometry>
        <mesh filename="package://dyros_red_lowerbody_description/meshes/Thigh_R_Link.stl" />
      </geometry>
      <material name="">
        <color rgba="0.85938 0.07813 0.23438 1" />
      </material>
    </visual>

    <collision>
      <origin xyz="0 0 0" rpy="0 0 0" />
      <geometry>
        <mesh filename="package://dyros_red_lowerbody_description/meshes/Thigh_R_Link.stl" />
      </geometry>
    </collision>
  </link>
  <joint name="Thigh_R_Joint" type="revolute">
    <origin xyz="0 0 0" rpy="0 0 0" />
    <parent link="HipCenter_R_Link" />
    <child link="Thigh_R_Link" />
    <axis xyz="0 1 0" />
    <limit effort="200" lower="-1.6581" upper="0.4014" velocity="2.09"/>
    <dynamics damping="10" />
  </joint>
  <link name="Knee_R_Link">
    <inertial>
      <origin xyz="0.00429 0.00214 -0.1428" rpy="0 0 0" />
      <mass value="4.072" />
      <inertia ixx="0.1579" ixy="-2.887E-05" ixz="-0.002734" iyy="1.443" iyz="-0.001558" izz="0.007814" />
    </inertial>
    <visual>
      <origin xyz="0 0 0" rpy="0 0 0" />
      <geometry>
        <mesh filename="package://dyros_red_lowerbody_description/meshes/Knee_R_Link.stl" />
      </geometry>
      <material name="">
        <color rgba="0.85938 0.07813 0.23438 1" />
      </material>
    </visual>
    <collision>
      <origin xyz="0 0 0" rpy="0 0 0" />
      <geometry>
        <mesh filename="package://dyros_red_lowerbody_description/meshes/Knee_R_Link.stl" />
      </geometry>
    </collision>
  </link>
  <joint name="Knee_R_Joint" type="revolute">
    <origin xyz="0 0 -0.35" rpy="0 0 0" />
    <parent link="Thigh_R_Link" />
    <child link="Knee_R_Link" />
    <axis xyz="0 1 0" />
    <limit effort="200" lower="-0.0218" upper="1.9722" velocity="6.0"/>
    <dynamics damping="10" />
  </joint>
  <link name="AnkleCenter_R_Link">
    <inertial>
      <origin xyz="-0.00419 -0.0018 -0.0003" rpy="0 0 0" />
      <mass value="2.693" />
      <inertia ixx="0.003065" ixy="-1.422E-07" ixz="2.222E-06" iyy="1.321" iyz="4.611E-06" izz="0.003589" />
    </inertial>
    <visual>
      <origin xyz="0 0 0" rpy="0 0 0" />
      <geometry>
        <mesh filename="package://dyros_red_lowerbody_description/meshes/AnkleCenter_R_Link.stl" />
      </geometry>
      <material name="">
        <color rgba="0.20313 0.20313 0.20313 1" />
      </material>
    </visual>
    <collision>
      <origin xyz="0 0 0" rpy="0 0 0" />
      <geometry>
        <mesh filename="package://dyros_red_lowerbody_description/meshes/AnkleCenter_R_Link.stl" />
      </geometry>
    </collision>
  </link>
  <joint name="AnkleCenter_R_Joint" type="revolute">
    <origin xyz="0 0 -0.35" rpy="0 0 0" />
    <parent link="Knee_R_Link" />
    <child link="AnkleCenter_R_Link" />
    <axis xyz="0 1 0" />
    <limit effort="200" lower="-1.5149" upper="1.7505" velocity="2.1"/>
    <dynamics damping="10" />
  </joint>
  <link name="AnkleRoll_R_Link">
    <inertial>
      <origin xyz="-0.00802 0 -0.08535" rpy="0 0 0" />
      <mass value="3.632" />
      <inertia ixx="0.4368" ixy="1.434E-05" ixz="-0.00496" iyy="0.0609" iyz="-2.508E-05" izz="0.02495" />
    </inertial>
    <visual>
      <origin xyz="0 0 0" rpy="0 0 0" />
      <geometry>
        <mesh filename="package://dyros_red_lowerbody_description/meshes/AnkleRoll_R_Link.stl" />
      </geometry>
      <material name="">
        <color rgba="0.85938 0.07813 0.23438 1" />
      </material>
    </visual>
    <collision>
      <origin xyz="0 0 0" rpy="0 0 0" />
      <geometry>
        <mesh filename="package://dyros_red_lowerbody_description/meshes/AnkleRoll_R_Link.stl" scale="1 1 1"/>
      </geometry>
    </collision>
  </link>
  <joint name="AnkleRoll_R_Joint" type="revolute">
    <origin xyz="0 0 0" rpy="0 0 0" />
    <parent link="AnkleCenter_R_Link" />
    <child link="AnkleRoll_R_Link" />
    <axis xyz="1 0 0" />
    <limit effort="200" lower="-0.3491" upper="0.3491" velocity="2.1"/>
    <dynamics damping="10" />
  </joint>
  <joint name="RLeg_effector_fixedjoint" type="fixed">
    <parent link="AnkleRoll_R_Link"/>
    <child link="r_sole"/>
    <origin rpy="0 0 0" xyz="0 0 -0.1451"/>
    <axis xyz="0 0 0"/>
  </joint>
  <link name="r_sole"/>
</robot>
